Workbook

Sheet FE Sales YR 1
B1: FRONT END SALES FORECAST | P1: **Green boxes can be changed to modify forecast
B2: 44734 | C2: 44764 | D2: 44795 | E2: 44826 | F2: 44856 | G2: 44887 | H2: 44948 | I2: 44980 | J2: 45008 | K2: 45039 | L2: 45067 | M2: 45098
A3: Month # | B3: 1 | C3: 2 | D3: 3 | E3: 4 | F3: 5 | G3: 6 | H3: 7 | I3: 8 | J3: 9 | K3: 10 | L3: 11 | M3: 12 | N3: TOTAL | P3: SALES TEAM
A4: FE SALES HEAD COUNT | P4: Position | Q4: Salary | R4: Comm %* | S4: Survey Fee%
N5: =SUM(M5) -> 0 | Q5: 0
A6: Business Coordinator | B6: 4 | C6: 4 | D6: 6 | E6: 6 | F6: 1 | G6: 6 | H6: 6 | I6: 3 | J6: 3 | K6: 3 | L6: 3 | M6: 3 | N6: =SUM(M6) -> 3 | P6: BC | Q6: 4000 | R6: 0.0125 | S6: 0
A7: Marketing Manager | B7: 1 | C7: 1 | D7: 1 | E7: 1 | F7: 1 | G7: 1 | H7: 1 | I7: 1 | J7: 1 | K7: 1 | L7: 1 | M7: 1 | N7: =SUM(M7) -> 1 | P7: Marketig Manager | Q7: 0 | R7: 0.01 | S7: 0.01
A8: Regional Marketing Director | B8: 3 | C8: 3 | D8: 4 | E8: 4 | F8: 4 | G8: 4 | H8: 6 | I8: 6 | J8: 6 | K8: 6 | L8: 6 | M8: 6 | N8: =SUM(M8) -> 6 | P8: RMD | Q8: 2000 | R8: 0.04 | S8: 0.5
A9: RSM | B9: 0 | C9: 0 | D9: 0 | E9: 0 | F9: 1 | G9: 0 | H9: 0 | I9: 0 | J9: 0 | K9: 0 | L9: 0 | M9: 0 | Q9: 0
A10: TOTAL | B10: =SUM(B5:B9) -> 8 | C10: =SUM(C5:C9) -> 8 | D10: =SUM(D5:D9) -> 11 | E10: =SUM(E5:E9) -> 11 | F10: 1 | G10: =SUM(G5:G9) -> 11 | H10: =SUM(H5:H9) -> 13 | I10: =SUM(I5:I9) -> 10 | J10: =SUM(J5:J9) -> 10 | K10: =SUM(K5:K9) -> 10 | L10: =SUM(L5:L9) -> 10 | M10: =SUM(M5:M9) -> 10 | N10: =SUM(N5:N9) -> 10 | R10: =SUM(R5:R9) -> 0.0625 | S10: =SUM(S5:S9) -> 0.51
A12: REVENUE | P12: ASSUMPTIONS
A13: Survey Fees | B13: =B8*$Q$13*$Q$14 -> 27000 | C13: =C8*$Q$13*$Q$14*50% -> 13500 | D13: =D8*$Q$13*$Q$14*75% -> 27000 | E13: =E8*$Q$13*$Q$14 -> 36000 | F13: =F8*$Q$13*$Q$14 -> 36000 | G13: =G8*$Q$13*$Q$14 -> 36000 | H13: =H8*$Q$13*$Q$14*75% -> 40500 | I13: =I8*$Q$13*$Q$14 -> 54000 | J13: =J8*$Q$13*$Q$14 -> 54000 | K13: =K8*$Q$13*$Q$14 -> 54000 | L13: =L8*$Q$13*$Q$14 -> 54000 | M13: =M8*$Q$13*$Q$14 -> 54000 | N13: =SUM(B13:M13) -> 486000 | P13: # Mo Sales per RMD | Q13: 5
A14: Cash Collect | B14: 0 | C14: =C6*$Q$13*$Q$15*$Q$16*$Q$17*40% -> 558400 | D14: =D6*$Q$13*$Q$15*$Q$16*$Q$17*60% -> 1256400 | E14: =E6*$Q$13*$Q$15*$Q$16*$Q$17*85% -> 1779900 | F14: =F6*$Q$13*$Q$15*$Q$16*$Q$17 -> 349000 | G14: =G6*$Q$13*$Q$15*$Q$16*$Q$17 -> 2094000 | H14: =H6*$Q$13*$Q$15*$Q$16*$Q$17*70% -> 1465800 | I14: =I6*$Q$13*$Q$15*$Q$16*$Q$17 -> 1047000 | J14: =J6*$Q$13*$Q$15*$Q$16*$Q$17 -> 1047000 | K14: =K6*$Q$13*$Q$15*$Q$16*$Q$17 -> 1047000 | L14: =L6*$Q$13*$Q$15*$Q$16*$Q$17 -> 1047000 | M14: =M6*$Q$13*$Q$15*$Q$16*$Q$17 -> 1047000 | N14: =SUM(B14:M14) -> 12738500 | P14: Avg Survey Fee | Q14: 1800
A15: TOTAL | B15: =SUM(B13:B14) -> 27000 | C15: =SUM(C13:C14) -> 571900 | D15: =SUM(D13:D14) -> 1283400 | E15: =SUM(E13:E14) -> 1815900 | F15: =SUM(F13:F14) -> 385000 | G15: =SUM(G13:G14) -> 2130000 | H15: =SUM(H13:H14) -> 1506300 | I15: =SUM(I13:I14) -> 1101000 | ... M15: =SUM(M13:M14) -> 1101000 | N15: =SUM(B15:M15) -> 13224500 | P15: Survey Closing % | Q15: 0.8
P16: Avg Hrs per Go | Q16: 250
A17: COST OF SALES | P17: Avg Rate per Hr | Q17: 349
A18: Salaries | B18: =SUM(B5*$Q$5+B6*$Q$6+C7*$Q$7+B8*$Q$8+B9*$Q$9+B13*S5+B13*S6+B13*S7+B13*S8+B13*S9)*50% -> 17885 | C18: =C5*$Q$5+C6*$Q$6+D7*$Q$7+C8*$Q$8+C9*$Q$9+C13*T5+C13*T6+C13*T7+C13*T8+C13*T9 -> 22000 | D18: =D5*$Q$5+D6*$Q$6+E7*$Q$7+D8*$Q$8+D9*$Q$9+D13*U5+D13*U6+D13*U7+D13*U8+D13*U9 -> 32000 | E18: =E5*$Q$5+E6*$Q$6+F7*$Q$7+E8*$Q$8+E9*$Q$9+E13*V5+E13*V6+E13*V7+E13*V8+E13*V9 -> 32000 | F18: =F5*$Q$5+F6*$Q$6+G7*$Q$7+F8*$Q$8+F9*$Q$9+F13*W5+F13*W6+F13*W7+F13*W8+F13*W9 -> 12000 | G18: =G5*$Q$5+G6*$Q$6+H7*$Q$7+G8*$Q$8+G9*$Q$9+G13*X5+G13*X6+G13*X7+G13*X8+G13*X9 -> 32000 | H18: =H5*$Q$5+H6*$Q$6+I7*$Q$7+H8*$Q$8+H9*$Q$9+H13*Y5+H13*Y6+H13*Y7+H13*Y8+H13*Y9 -> 36000 | I18: =I5*$Q$5+I6*$Q$6+J7*$Q$7+I8*$Q$8+I9*$Q$9+I13*Z5+I13*Z6+I13*Z7+I13*Z8+I13*Z9 -> 24000 | J18: =J5*$Q$5+J6*$Q$6+K7*$Q$7+J8*$Q$8+J9*$Q$9+J13*AA5+J13*AA6+J13*AA7+J13*AA8+J13*AA9 -> 24000 | ... M18: =M5*$Q$5+M6*$Q$6+N7*$Q$7+M8*$Q$8+M9*$Q$9+M13*AD5+M13*AD6+M13*AD7+M13*AD8+M13*AD9 -> 24000 | N18: =SUM(B18:M18) -> 303885 | P18: Est. Sale Bonuses | Q18: =IF(Q13>5,(Q13-4)*300,0) -> 0
A19: Commission | B19: =IF(B5>0,$R$5*B$14,0) -> 0 | C19: =IF(C5>0,$R$5*C$14,0) -> 0 | D19: =IF(D5>0,$R$5*D$14,0) -> 0 | E19: =IF(E5>0,$R$5*E$14,0) -> 0 | F19: =IF(F5>0,$R$5*F$14,0) -> 0 | G19: =IF(G5>0,$R$5*G$14,0) -> 0 | H19: =IF(H5>0,$R$5*H$14,0) -> 0 | I19: =IF(I5>0,$R$5*I$14,0) -> 0 | ... M19: =IF(M5>0,$R$5*M$14,0) -> 0 | N19: =SUM(B19:M19) -> 0 | P19: Est. Srvy Fee Bonus | Q19: =IF($Q$14>995,($Q$14-995)*0.5*$Q$13,0) -> 2012.5
A20: Bonus | B20: =IF(B8>0,B8*$Q$18+B8*$Q$19,0) -> 6037.5 | C20: =IF(C8>0,C8*$Q$18+C8*$Q$19,0) -> 6037.5 | D20: =IF(D8>0,D8*$Q$18+D8*$Q$19,0) -> 8050 | E20: =IF(E8>0,E8*$Q$18+E8*$Q$19,0) -> 8050 | F20: =IF(F8>0,F8*$Q$18+F8*$Q$19,0) -> 8050 | G20: =IF(G8>0,G8*$Q$18+G8*$Q$19,0) -> 8050 | H20: =IF(H8>0,H8*$Q$18+H8*$Q$19,0) -> 12075 | I20: =IF(I8>0,I8*$Q$18+I8*$Q$19,0) -> 12075 | ... M20: =IF(M8>0,M8*$Q$18+M8*$Q$19,0) -> 12075 | N20: =SUM(B20:M20) -> 116725
A21: FE Sales (Survey Fee %) | B21: =SUM(B13)*$S10 -> 13770 | C21: =SUM(C13)*$S10 -> 6885 | D21: =SUM(D13)*$S10 -> 13770 | E21: =SUM(E13)*$S10 -> 18360 | F21: =SUM(F13)*$S10 -> 18360 | G21: =SUM(G13)*$S10 -> 18360 | H21: =SUM(H13)*$S10 -> 20655 | I21: =SUM(I13)*$S10 -> 27540 | ... M21: =SUM(M13)*$S10 -> 27540 | N21: =SUM(B21:M21) -> 247860
A22: Payroll Burden (7.65%) | B22: =(B18+B19+B20)*0.0765 -> 1830.0712 | C22: =(C18+C19+C20)*0.0765 -> 2144.8688 | D22: =(D18+D19+D20)*0.0765 -> 3063.825 | E22: =(E18+E19+E20)*0.0765 -> 3063.825 | F22: =(F18+F19+F20)*0.0765 -> 1533.825 | G22: =(G18+G19+G20)*0.0765 -> 3063.825 | H22: =(H18+H19+H20)*0.0765 -> 3677.7375 | I22: =(I18+I19+I20)*0.0765 -> 2759.7375 | ... M22: =(M18+M19+M20)*0.0765 -> 2759.7375 | N22: =SUM(B22:M22) -> 32176.665
A23: Benefit Pkg ($700/emp) | H23: =SUM(H10)*700 -> 9100 | I23: =SUM(I10)*700 -> 7000 | J23: =SUM(J10)*700 -> 7000 | K23: =SUM(K10)*700 -> 7000 | L23: =SUM(L10)*700 -> 7000 | M23: =SUM(M10)*700 -> 7000 | N23: =SUM(B23:M23) -> 44100
A24: 401 K (Matching 3%) | H24: =SUM(H18:H21)*3% -> 2061.9 | I24: =SUM(I18:I21)*3% -> 1908.45 | J24: =SUM(J18:J21)*3% -> 1908.45 | K24: =SUM(K18:K21)*3% -> 1908.45 | L24: =SUM(L18:L21)*3% -> 1908.45 | M24: =SUM(M18:M21)*3% -> 1908.45 | N24: =SUM(B24:M24) -> 11604.15
A25: Leads | B25: 800 | C25: 800 | E25: =SUM(500*E8) -> 2000 | F25: =SUM(500*F8) -> 2000 | G25: =SUM(500*G8) -> 2000 | H25: =SUM(500*H8) -> 3000 | I25: =SUM(500*I8) -> 3000 | J25: =SUM(500*J8) -> 3000 | K25: =SUM(500*K8) -> 3000 | L25: =SUM(500*L8) -> 3000 | M25: =SUM(500*M8) -> 3000 | N25: =SUM(B25:M25) -> 25600
A26: CRM | B26: =39*B10+39 -> 351 | C26: =39*C10 -> 312 | D26: =39*D10 -> 429 | E26: =39*E10 -> 429 | F26: =39*F10 -> 39 | G26: =39*G10 -> 429 | H26: =39*H10 -> 507 | I26: =39*I10 -> 390 | J26: =39*J10 -> 390 | ... M26: =39*M10 -> 390 | N26: =SUM(B26:M26) -> 4446
A27: Phone (Phone, Voicemail, Video) | B27: =SUM(28*B6)+(52*B7)+52 -> 216 | C27: =SUM(28*C6)+(52*C7)+52 -> 216 | D27: =SUM(28*D6)+(52*D7)+52 -> 272 | E27: =SUM(28*E6)+(52*E7)+52 -> 272 | F27: =SUM(28*F6)+(52*F7)+52 -> 132 | G27: =SUM(28*G6)+(52*G7)+52 -> 272 | H27: =SUM(28*H6)+(52*H7)+52 -> 272 | I27: =SUM(28*I6)+(52*I7)+52 -> 188 | ... M27: =SUM(28*M6)+(52*M7)+52 -> 188 | N27: =SUM(B27:M27) -> 2592
A28: Recruiting Ads | B28: 850 | C28: 0 | D28: 0 | E28: 0 | F28: 0 | G28: 850 | H28: 850 | I28: 850 | J28: 850 | K28: 850 | L28: 850 | M28: 850 | N28: =SUM(B28:M28) -> 6800
A29: TSR Field Training | B29: =SUM(B8*500) -> 1500 | C29: 1800 | D29: 1800 | E29: =SUM(E8*750) -> 3000 | F29: =SUM(F8*750) -> 3000 | G29: =SUM(G8*750) -> 3000 | H29: =SUM(H8*750) -> 4500 | I29: =SUM(I8*750) -> 4500 | J29: =SUM(J8*750) -> 4500 | K29: =SUM(K8*750) -> 4500 | L29: =SUM(L8*750) -> 4500 | M29: =SUM(M8*750) -> 4500 | N29: =SUM(B29:M29) -> 41100
A30: TSR Per Diem | B30: =500*B8 -> 1500 | C30: =500*C8 -> 1500 | D30: =500*D8 -> 2000 | E30: =500*E8 -> 2000 | F30: =500*F8 -> 2000 | G30: =500*G8 -> 2000 | H30: =500*H8 -> 3000 | I30: =500*I8 -> 3000 | ... M30: =500*M8 -> 3000 | N30: =SUM(B30:M30) -> 29000
A31: TSR Car/Fuel Allowance | B31: =600*B8 -> 1800 | C31: =600*C8 -> 1800 | D31: =600*D8 -> 2400 | E31: =600*E8 -> 2400 | F31: =600*F8 -> 2400 | G31: =600*G8 -> 2400 | H31: =600*H8 -> 3600 | I31: =600*I8 -> 3600 | ... M31: =600*M8 -> 3600 | N31: =SUM(B31:M31) -> 34800
A32: TSR Phone Allowance | B32: =25*B8 -> 75 | C32: 40 | D32: =25*D8 -> 100 | E32: =25*E8 -> 100 | F32: =25*F8 -> 100 | G32: =25*G8 -> 100 | H32: =25*H8 -> 150 | I32: =25*I8 -> 150 | J32: =25*J8 -> 150 | K32: =25*K8 -> 150 | ... M32: =25*M8 -> 150 | N32: =SUM(B32:M32) -> 1415
A33: TSR Hotel-2wk/mo travel | B33: =1800*B8 -> 5400 | C33: =1800*C8 -> 5400 | D33: =1800*D8 -> 7200 | E33: =1800*E8 -> 7200 | F33: =1800*F8 -> 7200 | G33: =1800*G8 -> 7200 | H33: =1800*H8 -> 10800 | I33: =1800*I8 -> 10800 | ... M33: =1800*M8 -> 10800 | N33: =SUM(B33:M33) -> 104400
A34: CC Fees (Square/In-Field) | B34: =SUM(B13*4%) -> 1080 | C34: =SUM(C13*4%) -> 540 | D34: =SUM(D13*4%) -> 1080 | E34: =SUM(E13*4%) -> 1440 | F34: =SUM(F13*4%) -> 1440 | G34: =SUM(G13*4%) -> 1440 | H34: =SUM(H13*4%) -> 1620 | I34: =SUM(I13*4%) -> 2160 | ... M34: =SUM(M13*4%) -> 2160 | N34: =SUM(B34:M34) -> 19440
A35: Printing
A36: Brochures (Leave Behinds) | B36: 500 | C36: =SUM(C8)*50 -> 150 | D36: =SUM(D8)*50 -> 200 | E36: =SUM(E8)*50 -> 200 | F36: =SUM(F8)*50 -> 200 | G36: =SUM(G8)*50 -> 200 | H36: =SUM(H8)*50 -> 300 | I36: =SUM(I8)*50 -> 300 | J36: =SUM(J8)*50 -> 300 | ... M36: =SUM(M8)*50 -> 300 | N36: =SUM(B36:M36) -> 3250
A37: Agreements (2-part) | B37: 500 | C37: 0 | D37: 0 | E37: 0 | F37: 0 | G37: 0 | H37: 500 | I37: 0 | J37: 0 | K37: 0 | N37: =SUM(B37:M37) -> 1000
A38: Business Cards: TSR | B38: =SUM(B8*50) -> 150 | C38: =SUM(C8*105) -> 315 | D38: 0 | E38: 0 | F38: 0 | G38: 0 | H38: =SUM(H8*105) -> 630 | I38: 0 | J38: 0 | K38: 0 | L38: 0 | M38: 0 | N38: =SUM(B38:M38) -> 1095
A39: Business Cards: RSM | B39: =SUM(B9*50) -> 0 | C39: =SUM(C9*50) -> 0 | D39: =SUM(D9*50) -> 0 | E39: =SUM(E9*50) -> 0 | F39: =SUM(F9*50) -> 50 | G39: =SUM(G9*50) -> 0 | H39: =SUM(H9*105) -> 0 | I39: 0 | J39: 0 | K39: 0 | L39: 0 | M39: 0 | N39: =SUM(B39:M39) -> 50
A40: Business Cards: CSO | B40: =SUM(B5*105) -> 0 | C40: 0 | D40: 0 | E40: 0 | F40: 0 | G40: 0 | H40: 0 | I40: 0 | J40: 0 | K40: 0 | L40: 0 | M40: 0 | N40: =SUM(B40:M40) -> 0
A41: TOTAL | B41: =SUM(B18:B34) -> 53094.571 | C41: =SUM(C18:C34) -> 49475.369 | D41: =SUM(D18:D34) -> 72164.825 | E41: =SUM(E18:E34) -> 80314.825 | F41: =SUM(F18:F34) -> 58254.825 | G41: =SUM(G18:G34) -> 81164.825 | H41: =SUM(H18:H34) -> 111868.64 | I41: =SUM(I18:I34) -> 103921.19 | ... M41: =SUM(M18:M34) -> 103921.19 | N41: =SUM(B41:M41) -> 1025943.8
...

Sheet FE Sales YR 2
B1: FRONT END SALES FORECAST | P1: **Green boxes can be changed to modify forecast
B2: 45108 | C2: 45139 | D2: 45190 | E2: 45220 | F2: 45251 | G2: 45281 | H2: 45312 | I2: 45343 | J2: 45372 | K2: 45403 | L2: 45433 | M2: 45464
A3: Month # | B3: 1 | C3: 2 | D3: 3 | E3: 4 | F3: 5 | G3: 6 | H3: 7 | I3: 8 | J3: 9 | K3: 10 | L3: 11 | M3: 12 | N3: TOTAL | P3: SALES TEAM
A4: FE SALES HEAD COUNT | P4: Position | Q4: Salary | R4: Comm %* | S4: Survey Fee%
A5: CSO | B5: =SUM('FE Sales YR 1'!M5) -> 0 | C5: 1 | D5: 1 | E5: 1 | F5: 1 | G5: 1 | H5: 1 | I5: 1 | J5: 1 | K5: 1 | L5: 1 | M5: 1 | N5: =SUM(M5) -> 1 | P5: CSO | Q5: 0 | R5: 0.025 | S5: 0.025
A6: Business Coordinator | B6: =SUM('FE Sales YR 1'!M6) -> 3 | C6: 3 | D6: 3 | E6: 3 | F6: 3 | G6: 3 | H6: 6 | I6: 6 | J6: 6 | K6: 6 | L6: 6 | M6: 6 | N6: =SUM(M6) -> 6 | P6: BC | Q6: 2500 | R6: 0.0125 | S6: 0.0125
A7: Marketing Manager | B7: =SUM('FE Sales YR 1'!M7) -> 1 | C7: 1 | D7: 1 | E7: 1 | F7: 1 | G7: 1 | H7: 2 | I7: 2 | J7: 2 | K7: 2 | L7: 2 | M7: 2 | N7: =SUM(M7) -> 2 | P7: TMM | Q7: 0 | R7: 0.01 | S7: 0.01
A8: Regional Marketing Director | B8: =SUM('FE Sales YR 1'!M8) -> 6 | C8: 6 | D8: 6 | E8: 6 | F8: 6 | G8: 6 | H8: 12 | I8: 12 | J8: 12 | K8: 12 | L8: 12 | M8: 12 | N8: =SUM(M8) -> 12 | P8: TSR | Q8: 2500 | R8: 0.04 | S8: 0.5
A9: RSM | B9: =SUM('FE Sales YR 1'!M9) -> 0 | C9: 1 | D9: 1 | E9: 1 | F9: 1 | G9: 1 | H9: 2 | I9: 2 | J9: 2 | K9: 2 | L9: 2 | M9: 2 | N9: =SUM(M9) -> 2 | P9: RSM | Q9: 0 | R9: 0.0175 | S9: 0.05
A10: TOTAL | B10: =SUM(B5:B9) -> 10 | C10: =SUM(C5:C9) -> 12 | D10: =SUM(D5:D9) -> 12 | E10: =SUM(E5:E9) -> 12 | F10: =SUM(F5:F9) -> 12 | G10: =SUM(G5:G9) -> 12 | H10: =SUM(H5:H9) -> 23 | I10: =SUM(I5:I9) -> 23 | ... N10: =SUM(N5:N9) -> 23 | R10: =SUM(R5:R9) -> 0.105 | S10: =SUM(S5:S9) -> 0.5975
A12: REVENUE | P12: ASSUMPTIONS
A13: Survey Fees | B13: =B8*$Q$13*$Q$14 -> 29850 | C13: =C8*$Q$13*$Q$14 -> 29850 | D13: =D8*$Q$13*$Q$14 -> 29850 | E13: =E8*$Q$13*$Q$14 -> 29850 | F13: =F8*$Q$13*$Q$14 -> 29850 | G13: =G8*$Q$13*$Q$14 -> 29850 | H13: =H8*$Q$13*$Q$14*65% -> 38805 | I13: =I8*$Q$13*$Q$14*85% -> 50745 | J13: =J8*$Q$13*$Q$14 -> 59700 | K13: =K8*$Q$13*$Q$14 -> 59700 | L13: =L8*$Q$13*$Q$14 -> 59700 | M13: =M8*$Q$13*$Q$14 -> 59700 | N13: =SUM(B13:M13) -> 507450 | P13: # Mo Sales per TSR | Q13: 5
A14: Cash Collect | B14: =B8*$Q$13*$Q$15*$Q$16*$Q$17 -> 708000 | C14: =C8*$Q$13*$Q$15*$Q$16*$Q$17 -> 708000 | D14: =D8*$Q$13*$Q$15*$Q$16*$Q$17 -> 708000 | E14: =E8*$Q$13*$Q$15*$Q$16*$Q$17 -> 708000 | F14: =F8*$Q$13*$Q$15*$Q$16*$Q$17 -> 708000 | G14: =G8*$Q$13*$Q$15*$Q$16*$Q$17 -> 708000 | H14: =H8*$Q$13*$Q$15*$Q$16*$Q$17*65% -> 920400 | I14: =I8*$Q$13*$Q$15*$Q$16*$Q$17*85% -> 1203600 | J14: =J8*$Q$13*$Q$15*$Q$16*$Q$17 -> 1416000 | K14: =K8*$Q$13*$Q$15*$Q$16*$Q$17 -> 1416000 | L14: =L8*$Q$13*$Q$15*$Q$16*$Q$17 -> 1416000 | M14: =M8*$Q$13*$Q$15*$Q$16*$Q$17 -> 1416000 | N14: =SUM(B14:M14) -> 12036000 | P14: Avg Survey Fee | Q14: 995
A15: TOTAL | B15: =SUM(B13:B14) -> 737850 | C15: =SUM(C13:C14) -> 737850 | D15: =SUM(D13:D14) -> 737850 | E15: =SUM(E13:E14) -> 737850 | F15: =SUM(F13:F14) -> 737850 | G15: =SUM(G13:G14) -> 737850 | H15: =SUM(H13:H14) -> 959205 | I15: =SUM(I13:I14) -> 1254345 | ... M15: =SUM(M13:M14) -> 1475700 | N15: =SUM(B15:M15) -> 12543450 | P15: Survey Closing % | Q15: 0.5
P16: Avg Hrs per Go | Q16: 160
A17: COST OF SALES | P17: Avg Rate per Hr | Q17: 295
A18: Salaries | B18: =B5*$Q$5+B6*$Q$6+C7*$Q$7+B8*$Q$8+B9*$Q$9+B13*S5+B13*S6+B13*S7+B13*S8+B13*S9 -> 40335.375 | C18: =C5*$Q$5+C6*$Q$6+D7*$Q$7+C8*$Q$8+C9*$Q$9+C13*T5+C13*T6+C13*T7+C13*T8+C13*T9 -> 22500 | D18: =D5*$Q$5+D6*$Q$6+E7*$Q$7+D8*$Q$8+D9*$Q$9+D13*U5+D13*U6+D13*U7+D13*U8+D13*U9 -> 22500 | E18: =E5*$Q$5+E6*$Q$6+F7*$Q$7+E8*$Q$8+E9*$Q$9+E13*V5+E13*V6+E13*V7+E13*V8+E13*V9 -> 22500 | F18: =F5*$Q$5+F6*$Q$6+G7*$Q$7+F8*$Q$8+F9*$Q$9+F13*W5+F13*W6+F13*W7+F13*W8+F13*W9 -> 22500 | G18: =G5*$Q$5+G6*$Q$6+H7*$Q$7+G8*$Q$8+G9*$Q$9+G13*X5+G13*X6+G13*X7+G13*X8+G13*X9 -> 22500 | H18: =H5*$Q$5+H6*$Q$6+I7*$Q$7+H8*$Q$8+H9*$Q$9+H13*Y5+H13*Y6+H13*Y7+H13*Y8+H13*Y9 -> 45000 | I18: =I5*$Q$5+I6*$Q$6+J7*$Q$7+I8*$Q$8+I9*$Q$9+I13*Z5+I13*Z6+I13*Z7+I13*Z8+I13*Z9 -> 45000 | ... M18: =M5*$Q$5+M6*$Q$6+N7*$Q$7+M8*$Q$8+M9*$Q$9+M13*AD5+M13*AD6+M13*AD7+M13*AD8+M13*AD9 -> 45000 | N18: =SUM(B18:M18) -> 422835.38 | P18: Est. Sale Bonuses | Q18: =IF(Q13>5,(Q13-4)*300,0) -> 0
A19: Commission | B19: =IF(B5>0,$R$5*B$14,0) -> 0 | C19: =IF(C5>0,$R$5*C$14,0) -> 17700 | D19: =IF(D5>0,$R$5*D$14,0) -> 17700 | E19: =IF(E5>0,$R$5*E$14,0) -> 17700 | F19: =IF(F5>0,$R$5*F$14,0) -> 17700 | G19: =IF(G5>0,$R$5*G$14,0) -> 17700 | H19: =IF(H5>0,$R$5*H$14,0) -> 23010 | I19: =IF(I5>0,$R$5*I$14,0) -> 30090 | ... M19: =IF(M5>0,$R$5*M$14,0) -> 35400 | N19: =SUM(B19:M19) -> 283200 | P19: Est. Srvy Fee Bonus | Q19: =IF($Q$14>995,($Q$14-995)*0.5*$Q$13,0) -> 0
A20: Bonus | B20: =IF(B8>0,B8*$Q$18+B8*$Q$19,0) -> 0 | C20: =IF(C8>0,C8*$Q$18+C8*$Q$19,0) -> 0 | D20: =IF(D8>0,D8*$Q$18+D8*$Q$19,0) -> 0 | E20: =IF(E8>0,E8*$Q$18+E8*$Q$19,0) -> 0 | F20: =IF(F8>0,F8*$Q$18+F8*$Q$19,0) -> 0 | G20: =IF(G8>0,G8*$Q$18+G8*$Q$19,0) -> 0 | H20: =IF(H8>0,H8*$Q$18+H8*$Q$19,0) -> 0 | I20: =IF(I8>0,I8*$Q$18+I8*$Q$19,0) -> 0 | ... M20: =IF(M8>0,M8*$Q$18+M8*$Q$19,0) -> 0 | N20: =SUM(B20:M20) -> 0
A21: FE Sales (Survey Fee %) | B21: =SUM(B13)*$S10 -> 17835.375 | C21: =SUM(C13)*$S10 -> 17835.375 | D21: =SUM(D13)*$S10 -> 17835.375 | E21: =SUM(E13)*$S10 -> 17835.375 | F21: =SUM(F13)*$S10 -> 17835.375 | G21: =SUM(G13)*$S10 -> 17835.375 | H21: =SUM(H13)*$S10 -> 23185.988 | I21: =SUM(I13)*$S10 -> 30320.138 | ... M21: =SUM(M13)*$S10 -> 35670.75 | N21: =SUM(B21:M21) -> 303201.38
A22: Payroll Burden (7.65%) | B22: =(B18+B19+B20)*0.0765 -> 3085.6562 | C22: =(C18+C19+C20)*0.0765 -> 3075.3 | D22: =(D18+D19+D20)*0.0765 -> 3075.3 | E22: =(E18+E19+E20)*0.0765 -> 3075.3 | F22: =(F18+F19+F20)*0.0765 -> 3075.3 | G22: =(G18+G19+G20)*0.0765 -> 3075.3 | H22: =(H18+H19+H20)*0.0765 -> 5202.765 | I22: =(I18+I19+I20)*0.0765 -> 5744.385 | ... M22: =(M18+M19+M20)*0.0765 -> 6150.6 | N22: =SUM(B22:M22) -> 54011.706
A23: Benefit Pkg ($700/emp) | B23: =SUM(B10)*700 -> 7000 | C23: =SUM(C10)*700 -> 8400 | D23: =SUM(D10)*700 -> 8400 | E23: =SUM(E10)*700 -> 8400 | F23: =SUM(F10)*700 -> 8400 | G23: =SUM(G10)*700 -> 8400 | H23: =SUM(H10)*700 -> 16100 | I23: =SUM(I10)*700 -> 16100 | ... M23: =SUM(M10)*700 -> 16100 | N23: =SUM(B23:M23) -> 145600
A24: 401 K (Matching 3%) | B24: =SUM(B18:B21)*3% -> 1745.1225 | C24: =SUM(C18:C21)*3% -> 1741.0612 | D24: =SUM(D18:D21)*3% -> 1741.0612 | E24: =SUM(E18:E21)*3% -> 1741.0612 | F24: =SUM(F18:F21)*3% -> 1741.0612 | G24: =SUM(G18:G21)*3% -> 1741.0612 | H24: =SUM(H18:H21)*3% -> 2735.8796 | I24: =SUM(I18:I21)*3% -> 3162.3041 | ... M24: =SUM(M18:M21)*3% -> 3482.1225 | N24: =SUM(B24:M24) -> 30277.103
A25: Leads | B25: 800 | C25: 800 | D25: =SUM(500*D8) -> 3000 | E25: =SUM(500*E8) -> 3000 | F25: =SUM(500*F8) -> 3000 | G25: =SUM(500*G8) -> 3000 | H25: =SUM(500*H8) -> 6000 | I25: =SUM(500*I8) -> 6000 | J25: =SUM(500*J8) -> 6000 | K25: =SUM(500*K8) -> 6000 | ... M25: =SUM(500*M8) -> 6000 | N25: =SUM(B25:M25) -> 49600
A26: CRM | B26: =39*B10+39 -> 429 | C26: =39*C10 -> 468 | D26: =39*D10 -> 468 | E26: =39*E10 -> 468 | F26: =39*F10 -> 468 | G26: =39*G10 -> 468 | H26: =39*H10 -> 897 | I26: =39*I10 -> 897 | J26: =39*J10 -> 897 | ... M26: =39*M10 -> 897 | N26: =SUM(B26:M26) -> 8151
A27: Phone (Phone, Voicemail, Video) | B27: =SUM(28*B6)+(52*B7)+52 -> 188 | C27: =SUM(28*C6)+(52*C7)+52 -> 188 | D27: =SUM(28*D6)+(52*D7)+52 -> 188 | E27: =SUM(28*E6)+(52*E7)+52 -> 188 | F27: =SUM(28*F6)+(52*F7)+52 -> 188 | G27: =SUM(28*G6)+(52*G7)+52 -> 188 | H27: =SUM(28*H6)+(52*H7)+52 -> 324 | I27: =SUM(28*I6)+(52*I7)+52 -> 324 | ... M27: =SUM(28*M6)+(52*M7)+52 -> 324 | N27: =SUM(B27:M27) -> 3072
A28: Recruiting Ads | B28: 850 | C28: 850 | D28: 850 | E28: 850 | F28: 850 | G28: 850 | H28: 850 | I28: 850 | J28: 850 | K28: 850 | L28: 850 | M28: 850 | N28: =SUM(B28:M28) -> 10200
A29: TSR Field Training | B29: =SUM(B8*500) -> 3000 | C29: 1800 | D29: 1800 | E29: =SUM(E8*750) -> 4500 | F29: =SUM(F8*750) -> 4500 | G29: =SUM(G8*750) -> 4500 | H29: =SUM(H8*750) -> 9000 | I29: =SUM(I8*750) -> 9000 | J29: =SUM(J8*750) -> 9000 | K29: =SUM(K8*750) -> 9000 | L29: =SUM(L8*750) -> 9000 | M29: =SUM(M8*750) -> 9000 | N29: =SUM(B29:M29) -> 74100
A30: TSR Per Diem | B30: =500*B8 -> 3000 | C30: =500*C8 -> 3000 | D30: =500*D8 -> 3000 | E30: =500*E8 -> 3000 | F30: =500*F8 -> 3000 | G30: =500*G8 -> 3000 | H30: =500*H8 -> 6000 | I30: =500*I8 -> 6000 | ... M30: =500*M8 -> 6000 | N30: =SUM(B30:M30) -> 54000
A31: TSR Car/Fuel Allowance | B31: =600*B8 -> 3600 | C31: =600*C8 -> 3600 | D31: =600*D8 -> 3600 | E31: =600*E8 -> 3600 | F31: =600*F8 -> 3600 | G31: =600*G8 -> 3600 | H31: =600*H8 -> 7200 | I31: =600*I8 -> 7200 | ... M31: =600*M8 -> 7200 | N31: =SUM(B31:M31) -> 64800
A32: TSR Phone Allowance | B32: =25*B8 -> 150 | C32: =25*C8 -> 150 | D32: =25*D8 -> 150 | E32: =25*E8 -> 150 | F32: =25*F8 -> 150 | G32: =25*G8 -> 150 | H32: =25*H8 -> 300 | I32: =25*I8 -> 300 | ... M32: =25*M8 -> 300 | N32: =SUM(B32:M32) -> 2700
A33: TSR Hotel-2wk/mo travel | B33: =1800*B8 -> 10800 | C33: =1800*C8 -> 10800 | D33: =1800*D8 -> 10800 | E33: =1800*E8 -> 10800 | F33: =1800*F8 -> 10800 | G33: =1800*G8 -> 10800 | H33: =1800*H8 -> 21600 | I33: =1800*I8 -> 21600 | ... M33: =1800*M8 -> 21600 | N33: =SUM(B33:M33) -> 194400
A34: CC Fees (Square/In-Field) | B34: =SUM(B13*4%) -> 1194 | C34: =SUM(C13*4%) -> 1194 | D34: =SUM(D13*4%) -> 1194 | E34: =SUM(E13*4%) -> 1194 | F34: =SUM(F13*4%) -> 1194 | G34: =SUM(G13*4%) -> 1194 | H34: =SUM(H13*4%) -> 1552.2 | I34: =SUM(I13*4%) -> 2029.8 | ... M34: =SUM(M13*4%) -> 2388 | N34: =SUM(B34:M34) -> 20298
A35: Printing
A36: Brochures (Leave Behinds) | B36: 500 | C36: =SUM(C8)*50 -> 300 | D36: =SUM(D8)*50 -> 300 | E36: =SUM(E8)*50 -> 300 | F36: =SUM(F8)*50 -> 300 | G36: =SUM(G8)*50 -> 300 | H36: =SUM(H8)*50 -> 600 | I36: =SUM(I8)*50 -> 600 | J36: =SUM(J8)*50 -> 600 | ... M36: =SUM(M8)*50 -> 600 | N36: =SUM(B36:M36) -> 5600
A37: Agreements (2-part) | C37: 0 | D37: 0 | E37: 0 | F37: 0 | G37: 0 | H37: 750 | I37: 0 | J37: 0 | K37: 0 | N37: =SUM(B37:M37) -> 750
A38: Business Cards: TSR | C38: =SUM(C8*105) -> 630 | D38: 0 | E38: 0 | F38: 0 | G38: 0 | H38: =SUM(H8*105) -> 1260 | I38: 0 | J38: 0 | K38: 0 | L38: 0 | M38: 0 | N38: =SUM(B38:M38) -> 1890
A39: Business Cards: RSM | B39: =SUM(B9*56) -> 0 | H39: =SUM(H9*105) -> 210 | I39: 0 | J39: 0 | K39: 0 | L39: 0 | M39: 0 | N39: =SUM(B39:M39) -> 210
A40: Business Cards: CSO | B40: =SUM(B5*105) -> 0 | C40: 0 | D40: 0 | E40: 0 | F40: 0 | G40: 0 | H40: 0 | I40: 0 | J40: 0 | K40: 0 | L40: 0 | M40: 0 | N40: =SUM(B40:M40) -> 0
A41: TOTAL | B41: =SUM(B18:B34) -> 94012.529 | C41: =SUM(C18:C34) -> 94101.736 | D41: =SUM(D18:D34) -> 96301.736 | E41: =SUM(E18:E34) -> 99001.736 | F41: =SUM(F18:F34) -> 99001.736 | G41: =SUM(G18:G34) -> 99001.736 | H41: =SUM(H18:H34) -> 168957.83 | I41: =SUM(I18:I34) -> 184617.63 | ... M41: =SUM(M18:M34) -> 196362.47 | N41: =SUM(B41:M41) -> 1720446.6
...

Sheet FE Sales YR 3
B1: FRONT END SALES FORECAST | P1: **Green boxes can be changed to modify forecast
B2: 45798 | C2: 45829 | D2: 7/21/2025 08/21/2025 08/21/252 | E2: 45921 | F2: 45951 | G2: 45982 | H2: 46012 | I2: 45678 | J2: 44702 | K2: 44825 | L2: 44855 | M2: 44886
A3: Month # | B3: 1 | C3: 2 | D3: 3 | E3: 4 | F3: 5 | G3: 6 | H3: 7 | I3: 8 | J3: 9 | K3: 10 | L3: 11 | M3: 12 | N3: TOTAL | P3: SALES TEAM
A4: FE SALES HEAD COUNT | P4: Position | Q4: Salary | R4: Comm %* | S4: Survey Fee%
A5: CSO | B5: 0 | C5: 0 | D5: 0 | E5: 0 | F5: 0 | G5: 0 | H5: 0 | I5: 0 | J5: 0 | K5: 0 | L5: 0 | M5: 0 | N5: 0 | P5: CSO | Q5: 0 | R5: 0.02 | S5: 0.02
A6: BC | B6: 8 | C6: 8 | D6: 8 | E6: 8 | F6: 8 | G6: 8 | H6: 9 | I6: 9 | J6: 9 | K6: 9 | L6: 9 | M6: 9 | N6: =SUM(M6) -> 9 | P6: BC | Q6: 2500 | R6: 0.0125 | S6: 0.0125
A7: TMM | B7: =SUM('FE Sales YR 2'!N7) -> 2 | C7: 2 | D7: 2 | E7: 2 | F7: 2 | G7: 2 | H7: 3 | I7: 3 | J7: 3 | K7: 3 | L7: 3 | M7: 3 | N7: =SUM(M7) -> 3 | P7: TMM | Q7: 0 | R7: 0.01 | S7: 0.01
A8: TSR | B8: 6 | C8: 6 | D8: 6 | E8: 6 | F8: 6 | G8: 6 | H8: 6 | I8: 6 | J8: 6 | K8: 6 | L8: 6 | M8: 6 | N8: =SUM(M8) -> 6 | P8: TSR | Q8: 2000 | R8: 0.04 | S8: 0.5
A9: RSM | B9: 0 | C9: 0 | D9: 0 | E9: 0 | F9: 0 | G9: 0 | H9: 0 | I9: 0 | J9: 0 | K9: 0 | L9: 0 | M9: 0 | N9: =SUM(M9) -> 0 | P9: RSM | Q9: 0 | R9: 0.02 | S9: 0.05
A10: TOTAL | B10: =SUM(B5:B9) -> 16 | C10: =SUM(C5:C9) -> 16 | D10: =SUM(D5:D9) -> 16 | E10: =SUM(E5:E9) -> 16 | F10: =SUM(F5:F9) -> 16 | G10: =SUM(G5:G9) -> 16 | H10: =SUM(H5:H9) -> 18 | I10: =SUM(I5:I9) -> 18 | ... N10: =SUM(N5:N9) -> 18 | R10: =SUM(R5:R9) -> 0.1025 | S10: =SUM(S5:S9) -> 0.5925
A12: REVENUE | P12: ASSUMPTIONS
A13: Survey Fees | B13: =B8*$Q$13*$Q$14 -> 29850 | C13: =C8*$Q$13*$Q$14 -> 29850 | D13: =D8*$Q$13*$Q$14 -> 29850 | E13: =E8*$Q$13*$Q$14 -> 29850 | F13: =F8*$Q$13*$Q$14 -> 29850 | G13: =G8*$Q$13*$Q$14 -> 29850 | H13: =H8*$Q$13*$Q$14*60% -> 17910 | I13: =I8*$Q$13*$Q$14*85% -> 25372.5 | J13: =J8*$Q$13*$Q$14 -> 29850 | K13: =K8*$Q$13*$Q$14 -> 29850 | L13: =L8*$Q$13*$Q$14 -> 29850 | M13: =M8*$Q$13*$Q$14 -> 29850 | N13: =SUM(B13:M13) -> 341782.5 | P13: # Mo Sales per TSR | Q13: 5
A14: Cash Collect | B14: =B8*$Q$13*$Q$15*$Q$16*$Q$17 -> 708000 | C14: =C8*$Q$13*$Q$15*$Q$16*$Q$17 -> 708000 | D14: =D8*$Q$13*$Q$15*$Q$16*$Q$17 -> 708000 | E14: =E8*$Q$13*$Q$15*$Q$16*$Q$17 -> 708000 | F14: =F8*$Q$13*$Q$15*$Q$16*$Q$17 -> 708000 | G14: =G8*$Q$13*$Q$15*$Q$16*$Q$17 -> 708000 | H14: =H8*$Q$13*$Q$15*$Q$16*$Q$17*60% -> 424800 | I14: =I8*$Q$13*$Q$15*$Q$16*$Q$17*85% -> 601800 | J14: =J8*$Q$13*$Q$15*$Q$16*$Q$17 -> 708000 | K14: =K8*$Q$13*$Q$15*$Q$16*$Q$17 -> 708000 | L14: =L8*$Q$13*$Q$15*$Q$16*$Q$17 -> 708000 | M14: =M8*$Q$13*$Q$15*$Q$16*$Q$17 -> 708000 | N14: =SUM(B14:M14) -> 8106600 | P14: Avg Survey Fee | Q14: 995
A15: TOTAL | B15: =SUM(B13:B14) -> 737850 | C15: =SUM(C13:C14) -> 737850 | D15: =SUM(D13:D14) -> 737850 | E15: =SUM(E13:E14) -> 737850 | F15: =SUM(F13:F14) -> 737850 | G15: =SUM(G13:G14) -> 737850 | H15: =SUM(H13:H14) -> 442710 | I15: =SUM(I13:I14) -> 627172.5 | ... N15: =SUM(N13:N14) -> 8448382.5 | P15: Survey Closing % | Q15: 0.5
P16: Avg Hrs per Go | Q16: 160
A17: COST OF SALES | P17: Avg Rate per Hr | Q17: 295
A18: Salaries | B18: =B5*$Q$5+B6*$Q$6+C7*$Q$7+B8*$Q$8+B9*$Q$9+B13*S5+B13*S6+B13*S7+B13*S8+B13*S9 -> 49686.125 | C18: =C5*$Q$5+C6*$Q$6+D7*$Q$7+C8*$Q$8+C9*$Q$9+C13*T5+C13*T6+C13*T7+C13*T8+C13*T9 -> 32000 | D18: =D5*$Q$5+D6*$Q$6+E7*$Q$7+D8*$Q$8+D9*$Q$9+D13*U5+D13*U6+D13*U7+D13*U8+D13*U9 -> 32000 | E18: =E5*$Q$5+E6*$Q$6+F7*$Q$7+E8*$Q$8+E9*$Q$9+E13*V5+E13*V6+E13*V7+E13*V8+E13*V9 -> 32000 | F18: =F5*$Q$5+F6*$Q$6+G7*$Q$7+F8*$Q$8+F9*$Q$9+F13*W5+F13*W6+F13*W7+F13*W8+F13*W9 -> 32000 | G18: =G5*$Q$5+G6*$Q$6+H7*$Q$7+G8*$Q$8+G9*$Q$9+G13*X5+G13*X6+G13*X7+G13*X8+G13*X9 -> 32000 | H18: =H5*$Q$5+H6*$Q$6+I7*$Q$7+H8*$Q$8+H9*$Q$9+H13*Y5+H13*Y6+H13*Y7+H13*Y8+H13*Y9 -> 34500 | I18: =I5*$Q$5+I6*$Q$6+J7*$Q$7+I8*$Q$8+I9*$Q$9+I13*Z5+I13*Z6+I13*Z7+I13*Z8+I13*Z9 -> 34500 | ... M18: =M5*$Q$5+M6*$Q$6+N7*$Q$7+M8*$Q$8+M9*$Q$9+M13*AD5+M13*AD6+M13*AD7+M13*AD8+M13*AD9 -> 34500 | N18: =SUM(B18:M18) -> 416686.12 | P18: Est. Sale Bonuses | Q18: =IF(Q13>5,(Q13-4)*300,0) -> 0
A19: Commission | B19: =IF(B5>0,$R$5*B$14,0) -> 0 | C19: =IF(C5>0,$R$5*C$14,0) -> 0 | D19: =IF(D5>0,$R$5*D$14,0) -> 0 | E19: =IF(E5>0,$R$5*E$14,0) -> 0 | F19: =IF(F5>0,$R$5*F$14,0) -> 0 | G19: =IF(G5>0,$R$5*G$14,0) -> 0 | H19: =IF(H5>0,$R$5*H$14,0) -> 0 | I19: =IF(I5>0,$R$5*I$14,0) -> 0 | ... M19: =IF(M5>0,$R$5*M$14,0) -> 0 | N19: =SUM(B19:M19) -> 0 | P19: Est. Srvy Fee Bonus | Q19: =IF($Q$14>995,($Q$14-995)*0.5*$Q$13,0) -> 0
A20: Bonus | B20: =IF(B8>0,B8*$Q$18+B8*$Q$19,0) -> 0 | C20: =IF(C8>0,C8*$Q$18+C8*$Q$19,0) -> 0 | D20: =IF(D8>0,D8*$Q$18+D8*$Q$19,0) -> 0 | E20: =IF(E8>0,E8*$Q$18+E8*$Q$19,0) -> 0 | F20: =IF(F8>0,F8*$Q$18+F8*$Q$19,0) -> 0 | G20: =IF(G8>0,G8*$Q$18+G8*$Q$19,0) -> 0 | H20: =IF(H8>0,H8*$Q$18+H8*$Q$19,0) -> 0 | I20: =IF(I8>0,I8*$Q$18+I8*$Q$19,0) -> 0 | ... M20: =IF(M8>0,M8*$Q$18+M8*$Q$19,0) -> 0 | N20: =SUM(B20:M20) -> 0
A21: FE Sales (Survey Fee %) | B21: =SUM(B13)*$S10 -> 17686.125 | C21: =SUM(C13)*$S10 -> 17686.125 | D21: =SUM(D13)*$S10 -> 17686.125 | E21: =SUM(E13)*$S10 -> 17686.125 | F21: =SUM(F13)*$S10 -> 17686.125 | G21: =SUM(G13)*$S10 -> 17686.125 | H21: =SUM(H13)*$S10 -> 10611.675 | I21: =SUM(I13)*$S10 -> 15033.206 | ... M21: =SUM(M13)*$S10 -> 17686.125 | N21: =SUM(B21:M21) -> 202506.13
A22: Payroll Burden (7.65%) | B22: =(B18+B19+B20)*0.0765 -> 3800.9886 | C22: =(C18+C19+C20)*0.0765 -> 2448 | D22: =(D18+D19+D20)*0.0765 -> 2448 | E22: =(E18+E19+E20)*0.0765 -> 2448 | F22: =(F18+F19+F20)*0.0765 -> 2448 | G22: =(G18+G19+G20)*0.0765 -> 2448 | H22: =(H18+H19+H20)*0.0765 -> 2639.25 | I22: =(I18+I19+I20)*0.0765 -> 2639.25 | ... M22: =(M18+M19+M20)*0.0765 -> 2639.25 | N22: =SUM(B22:M22) -> 31876.489
A23: Benefit Pkg ($700/emp) | B23: =SUM(B10)*700 -> 11200 | C23: =SUM(C10)*700 -> 11200 | D23: =SUM(D10)*700 -> 11200 | E23: =SUM(E10)*700 -> 11200 | F23: =SUM(F10)*700 -> 11200 | G23: =SUM(G10)*700 -> 11200 | H23: =SUM(H10)*700 -> 12600 | I23: =SUM(I10)*700 -> 12600 | ... M23: =SUM(M10)*700 -> 12600 | N23: =SUM(B23:M23) -> 142800
A24: 401 K (Matching 3%) | B24: =SUM(B18:B21)*3% -> 2021.1675 | C24: =SUM(C18:C21)*3% -> 1490.5838 | D24: =SUM(D18:D21)*3% -> 1490.5838 | E24: =SUM(E18:E21)*3% -> 1490.5838 | F24: =SUM(F18:F21)*3% -> 1490.5838 | G24: =SUM(G18:G21)*3% -> 1490.5838 | H24: =SUM(H18:H21)*3% -> 1353.3502 | I24: =SUM(I18:I21)*3% -> 1485.9962 | ... M24: =SUM(M18:M21)*3% -> 1565.5838 | N24: =SUM(B24:M24) -> 18575.768
A25: Leads | B25: 800 | C25: 800 | D25: =SUM(500*D8) -> 3000 | E25: =SUM(500*E8) -> 3000 | F25: =SUM(500*F8) -> 3000 | G25: =SUM(500*G8) -> 3000 | H25: =SUM(500*H8) -> 3000 | I25: =SUM(500*I8) -> 3000 | J25: =SUM(500*J8) -> 3000 | K25: =SUM(500*K8) -> 3000 | ... M25: =SUM(500*M8) -> 3000 | N25: =SUM(B25:M25) -> 31600
A26: CRM | B26: =39*B10+39 -> 663 | C26: =39*C10 -> 624 | D26: =39*D10 -> 624 | E26: =39*E10 -> 624 | F26: =39*F10 -> 624 | G26: =39*G10 -> 624 | H26: =39*H10 -> 702 | I26: =39*I10 -> 702 | J26: =39*J10 -> 702 | ... M26: =39*M10 -> 702 | N26: =SUM(B26:M26) -> 7995
A27: Phone (Phone, Voicemail, Video) | B27: =SUM(28*B6)+(52*B7)+52 -> 380 | C27: =SUM(28*C6)+(52*C7)+52 -> 380 | D27: =SUM(28*D6)+(52*D7)+52 -> 380 | E27: =SUM(28*E6)+(52*E7)+52 -> 380 | F27: =SUM(28*F6)+(52*F7)+52 -> 380 | G27: =SUM(28*G6)+(52*G7)+52 -> 380 | H27: =SUM(28*H6)+(52*H7)+52 -> 460 | I27: =SUM(28*I6)+(52*I7)+52 -> 460 | ... M27: =SUM(28*M6)+(52*M7)+52 -> 460 | N27: =SUM(B27:M27) -> 5040
A28: Recruiting Ads | B28: 850 | C28: 850 | D28: 850 | E28: 850 | F28: 850 | G28: 850 | H28: 850 | I28: 850 | J28: 850 | K28: 850 | L28: 850 | M28: 850 | N28: =SUM(B28:M28) -> 10200
A29: TSR Field Training | B29: =SUM(B8*500) -> 3000 | C29: 1800 | D29: 1800 | E29: =SUM(E8*750) -> 4500 | F29: =SUM(F8*750) -> 4500 | G29: =SUM(G8*750) -> 4500 | H29: =SUM(H8*750) -> 4500 | I29: =SUM(I8*750) -> 4500 | J29: =SUM(J8*750) -> 4500 | K29: =SUM(K8*750) -> 4500 | L29: =SUM(L8*750) -> 4500 | M29: =SUM(M8*750) -> 4500 | N29: =SUM(B29:M29) -> 47100
A30: TSR Per Diem | B30: =500*B8 -> 3000 | C30: =500*C8 -> 3000 | D30: =500*D8 -> 3000 | E30: =500*E8 -> 3000 | F30: =500*F8 -> 3000 | G30: =500*G8 -> 3000 | H30: =500*H8 -> 3000 | I30: =500*I8 -> 3000 | ... M30: =500*M8 -> 3000 | N30: =SUM(B30:M30) -> 36000
A31: TSR Car/Fuel Allowance | B31: =600*B8 -> 3600 | C31: =600*C8 -> 3600 | D31: =600*D8 -> 3600 | E31: =600*E8 -> 3600 | F31: =600*F8 -> 3600 | G31: =600*G8 -> 3600 | H31: =600*H8 -> 3600 | I31: =600*I8 -> 3600 | ... M31: =600*M8 -> 3600 | N31: =SUM(B31:M31) -> 43200
A32: TSR Phone Allowance | B32: =25*B8 -> 150 | C32: =25*C8 -> 150 | D32: =25*D8 -> 150 | E32: =25*E8 -> 150 | F32: =25*F8 -> 150 | G32: =25*G8 -> 150 | H32: =25*H8 -> 150 | I32: =25*I8 -> 150 | ... M32: =25*M8 -> 150 | N32: =SUM(B32:M32) -> 1800
A33: TSR Hotel-2wk/mo travel | B33: =1800*B8 -> 10800 | C33: =1800*C8 -> 10800 | D33: =1800*D8 -> 10800 | E33: =1800*E8 -> 10800 | F33: =1800*F8 -> 10800 | G33: =1800*G8 -> 10800 | H33: =1800*H8 -> 10800 | I33: =1800*I8 -> 10800 | ... M33: =1800*M8 -> 10800 | N33: =SUM(B33:M33) -> 129600
A34: CC Fees (Square/In-Field) | B34: =SUM(B13*4%) -> 1194 | C34: =SUM(C13*4%) -> 1194 | D34: =SUM(D13*4%) -> 1194 | E34: =SUM(E13*4%) -> 1194 | F34: =SUM(F13*4%) -> 1194 | G34: =SUM(G13*4%) -> 1194 | H34: =SUM(H13*4%) -> 716.4 | I34: =SUM(I13*4%) -> 1014.9 | ... M34: =SUM(M13*4%) -> 1194 | N34: =SUM(B34:M34) -> 13671.3
A35: Printing
A36: Brochures (Leave Behinds) | B36: 500 | C36: =SUM(C8)*50 -> 300 | D36: =SUM(D8)*50 -> 300 | E36: =SUM(E8)*50 -> 300 | F36: =SUM(F8)*50 -> 300 | G36: =SUM(G8)*50 -> 300 | H36: =SUM(H8)*50 -> 300 | I36: =SUM(I8)*50 -> 300 | J36: =SUM(J8)*50 -> 300 | ... M36: =SUM(M8)*50 -> 300 | N36: =SUM(B36:M36) -> 3800
A37: Agreements (2-part) | C37: 0 | D37: 0 | E37: 0 | F37: 0 | G37: 0 | H37: 750 | I37: 0 | J37: 0 | K37: 0 | N37: =SUM(B37:M37) -> 750
A38: Business Cards: TSR | C38: =SUM(C8*105) -> 630 | D38: 0 | E38: 0 | F38: 0 | G38: 0 | H38: =SUM(H8*105) -> 630 | I38: 0 | J38: 0 | K38: 0 | L38: 0 | M38: 0 | N38: =SUM(B38:M38) -> 1260
A39: Business Cards: RSM | B39: =SUM(B9*56) -> 0 | H39: =SUM(H9*105) -> 0 | I39: 0 | J39: 0 | K39: 0 | L39: 0 | M39: 0 | N39: =SUM(B39:M39) -> 0
A40: Business Cards: CSO | B40: =SUM(B5*105) -> 0 | C40: 0 | D40: 0 | E40: 0 | F40: 0 | G40: 0 | H40: 0 | I40: 0 | J40: 0 | K40: 0 | L40: 0 | M40: 0 | N40: =SUM(B40:M40) -> 0
A41: TOTAL | B41: =SUM(B18:B34) -> 108831.41 | C41: =SUM(C18:C34) -> 88022.709 | D41: =SUM(D18:D34) -> 90222.709 | E41: =SUM(E18:E34) -> 92922.709 | F41: =SUM(F18:F34) -> 92922.709 | G41: =SUM(G18:G34) -> 92922.709 | H41: =SUM(H18:H34) -> 89482.675 | I41: =SUM(I18:I34) -> 94335.352 | ... M41: =SUM(M18:M34) -> 97246.959 | N41: =SUM(B41:M41) -> 1138650.8
...

Sheet FE Sales YR 4
B1: FRONT END SALES FORECAST | P1: **Green boxes can be changed to modify forecast
B2: 44551 | C2: 44582 | D2: 44613 | E2: 44641 | F2: 44672 | G2: 44702 | H2: 44733 | I2: 44763 | J2: 44794 | K2: 44825 | L2: 44855 | M2: 44886
A3: Month # | B3: 1 | C3: 2 | D3: 3 | E3: 4 | F3: 5 | G3: 6 | H3: 7 | I3: 8 | J3: 9 | K3: 10 | L3: 11 | M3: 12 | N3: TOTAL | P3: SALES TEAM
A4: FE SALES HEAD COUNT | P4: Position | Q4: Salary | R4: Comm %* | S4: Survey Fee%
A5: CSO | B5: =SUM('FE Sales YR 3'!M5) -> 0 | C5: 1 | D5: 1 | E5: 1 | F5: 1 | G5: 1 | H5: 1 | I5: 1 | J5: 1 | K5: 1 | L5: 1 | M5: 1 | N5: =SUM(M5) -> 1 | P5: CSO | Q5: 0 | R5: 0.0175 | S5: 0.0175
A6: BC | B6: =SUM('FE Sales YR 3'!M6) -> 9 | C6: 9 | D6: 9 | E6: 9 | F6: 9 | G6: 9 | H6: 12 | I6: 12 | J6: 12 | K6: 12 | L6: 12 | M6: 12 | N6: =SUM(M6) -> 12 | P6: BC | Q6: 2500 | R6: 0.0125 | S6: 0.0125
A7: TMM | B7: =SUM('FE Sales YR 3'!M7) -> 3 | C7: 3 | D7: 3 | E7: 3 | F7: 3 | G7: 3 | H7: 4 | I7: 4 | J7: 4 | K7: 4 | L7: 4 | M7: 4 | N7: =SUM(M7) -> 4 | P7: TMM | Q7: 0 | R7: 0.01 | S7: 0.01
A8: TSR | B8: =SUM('FE Sales YR 3'!M8) -> 6 | C8: 18 | D8: 18 | E8: 18 | F8: 18 | G8: 18 | H8: 24 | I8: 24 | J8: 24 | K8: 24 | L8: 24 | M8: 24 | N8: =SUM(M8) -> 24 | P8: TSR | Q8: 2000 | R8: 0.04 | S8: 0.5
A9: RSM | B9: =SUM('FE Sales YR 3'!M9) -> 0 | C9: 3 | D9: 3 | E9: 3 | F9: 3 | G9: 3 | H9: 4 | I9: 4 | J9: 4 | K9: 4 | L9: 4 | M9: 4 | N9: =SUM(M9) -> 4 | P9: RSM | Q9: 0 | R9: 0.0175 | S9: 0.05
A10: TOTAL | B10: =SUM(B5:B9) -> 18 | C10: =SUM(C5:C9) -> 34 | D10: =SUM(D5:D9) -> 34 | E10: =SUM(E5:E9) -> 34 | F10: =SUM(F5:F9) -> 34 | G10: =SUM(G5:G9) -> 34 | H10: =SUM(H5:H9) -> 45 | I10: =SUM(I5:I9) -> 45 | ... N10: =SUM(N5:N9) -> 45 | R10: =SUM(R5:R9) -> 0.0975 | S10: =SUM(S5:S9) -> 0.59
A12: REVENUE | P12: ASSUMPTIONS
A13: Survey Fees | B13: =B8*$Q$13*$Q$14 -> 29850 | C13: =C8*$Q$13*$Q$14 -> 89550 | D13: =D8*$Q$13*$Q$14 -> 89550 | E13: =E8*$Q$13*$Q$14 -> 89550 | F13: =F8*$Q$13*$Q$14 -> 89550 | G13: =G8*$Q$13*$Q$14 -> 89550 | H13: =H8*$Q$13*$Q$14*85% -> 101490 | I13: =I8*$Q$13*$Q$14*90% -> 107460 | J13: =J8*$Q$13*$Q$14 -> 119400 | K13: =K8*$Q$13*$Q$14 -> 119400 | L13: =L8*$Q$13*$Q$14 -> 119400 | M13: =M8*$Q$13*$Q$14 -> 119400 | N13: =SUM(B13:M13) -> 1164150 | P13: # Mo Sales per TSR | Q13: 5
A14: Cash Collect | B14: =B8*$Q$13*$Q$15*$Q$16*$Q$17 -> 708000 | C14: =C8*$Q$13*$Q$15*$Q$16*$Q$17 -> 2124000 | D14: =D8*$Q$13*$Q$15*$Q$16*$Q$17 -> 2124000 | E14: =E8*$Q$13*$Q$15*$Q$16*$Q$17 -> 2124000 | F14: =F8*$Q$13*$Q$15*$Q$16*$Q$17 -> 2124000 | G14: =G8*$Q$13*$Q$15*$Q$16*$Q$17 -> 2124000 | H14: =H8*$Q$13*$Q$15*$Q$16*$Q$17*85% -> 2407200 | I14: =I8*$Q$13*$Q$15*$Q$16*$Q$17*90% -> 2548800 | J14: =J8*$Q$13*$Q$15*$Q$16*$Q$17 -> 2832000 | K14: =K8*$Q$13*$Q$15*$Q$16*$Q$17 -> 2832000 | L14: =L8*$Q$13*$Q$15*$Q$16*$Q$17 -> 2832000 | M14: =M8*$Q$13*$Q$15*$Q$16*$Q$17 -> 2832000 | N14: =SUM(B14:M14) -> 27612000 | P14: Avg Survey Fee | Q14: 995
A15: TOTAL | B15: =SUM(B13:B14) -> 737850 | C15: =SUM(C13:C14) -> 2213550 | D15: =SUM(D13:D14) -> 2213550 | E15: =SUM(E13:E14) -> 2213550 | F15: =SUM(F13:F14) -> 2213550 | G15: =SUM(G13:G14) -> 2213550 | H15: =SUM(H13:H14) -> 2508690 | I15: =SUM(I13:I14) -> 2656260 | ... M15: =SUM(M13:M14) -> 2951400 | N15: =SUM(B15:M15) -> 28776150 | P15: Survey Closing % | Q15: 0.5
P16: Avg Hrs per Go | Q16: 160
A17: COST OF SALES | P17: Avg Rate per Hr | Q17: 295
A18: Salaries | B18: =B5*$Q$5+B6*$Q$6+C7*$Q$7+B8*$Q$8+B9*$Q$9+B13*S5+B13*S6+B13*S7+B13*S8+B13*S9 -> 52111.5 | C18: =C5*$Q$5+C6*$Q$6+D7*$Q$7+C8*$Q$8+C9*$Q$9+C13*T5+C13*T6+C13*T7+C13*T8+C13*T9 -> 58500 | D18: =D5*$Q$5+D6*$Q$6+E7*$Q$7+D8*$Q$8+D9*$Q$9+D13*U5+D13*U6+D13*U7+D13*U8+D13*U9 -> 58500 | E18: =E5*$Q$5+E6*$Q$6+F7*$Q$7+E8*$Q$8+E9*$Q$9+E13*V5+E13*V6+E13*V7+E13*V8+E13*V9 -> 58500 | F18: =F5*$Q$5+F6*$Q$6+G7*$Q$7+F8*$Q$8+F9*$Q$9+F13*W5+F13*W6+F13*W7+F13*W8+F13*W9 -> 58500 | G18: =G5*$Q$5+G6*$Q$6+H7*$Q$7+G8*$Q$8+G9*$Q$9+G13*X5+G13*X6+G13*X7+G13*X8+G13*X9 -> 58500 | H18: =H5*$Q$5+H6*$Q$6+I7*$Q$7+H8*$Q$8+H9*$Q$9+H13*Y5+H13*Y6+H13*Y7+H13*Y8+H13*Y9 -> 78000 | I18: =I5*$Q$5+I6*$Q$6+J7*$Q$7+I8*$Q$8+I9*$Q$9+I13*Z5+I13*Z6+I13*Z7+I13*Z8+I13*Z9 -> 78000 | ... M18: =M5*$Q$5+M6*$Q$6+N7*$Q$7+M8*$Q$8+M9*$Q$9+M13*AD5+M13*AD6+M13*AD7+M13*AD8+M13*AD9 -> 78000 | N18: =SUM(B18:M18) -> 812611.5 | P18: Est. Sale Bonuses | Q18: =IF(Q13>5,(Q13-4)*300,0) -> 0
A19: Commission | B19: =IF(B5>0,$R$5*B$14,0) -> 0 | C19: =IF(C5>0,$R$5*C$14,0) -> 37170 | D19: =IF(D5>0,$R$5*D$14,0) -> 37170 | E19: =IF(E5>0,$R$5*E$14,0) -> 37170 | F19: =IF(F5>0,$R$5*F$14,0) -> 37170 | G19: =IF(G5>0,$R$5*G$14,0) -> 37170 | H19: =IF(H5>0,$R$5*H$14,0) -> 42126 | I19: =IF(I5>0,$R$5*I$14,0) -> 44604 | ... M19: =IF(M5>0,$R$5*M$14,0) -> 49560 | N19: =SUM(B19:M19) -> 470820 | P19: Est. Srvy Fee Bonus | Q19: =IF($Q$14>995,($Q$14-995)*0.5*$Q$13,0) -> 0
A20: Bonus | B20: =IF(B8>0,B8*$Q$18+B8*$Q$19,0) -> 0 | C20: =IF(C8>0,C8*$Q$18+C8*$Q$19,0) -> 0 | D20: =IF(D8>0,D8*$Q$18+D8*$Q$19,0) -> 0 | E20: =IF(E8>0,E8*$Q$18+E8*$Q$19,0) -> 0 | F20: =IF(F8>0,F8*$Q$18+F8*$Q$19,0) -> 0 | G20: =IF(G8>0,G8*$Q$18+G8*$Q$19,0) -> 0 | H20: =IF(H8>0,H8*$Q$18+H8*$Q$19,0) -> 0 | I20: =IF(I8>0,I8*$Q$18+I8*$Q$19,0) -> 0 | ... M20: =IF(M8>0,M8*$Q$18+M8*$Q$19,0) -> 0 | N20: =SUM(B20:M20) -> 0
A21: FE Sales (Survey Fee %) | B21: =SUM(B13)*$S10 -> 17611.5 | C21: =SUM(C13)*$S10 -> 52834.5 | D21: =SUM(D13)*$S10 -> 52834.5 | E21: =SUM(E13)*$S10 -> 52834.5 | F21: =SUM(F13)*$S10 -> 52834.5 | G21: =SUM(G13)*$S10 -> 52834.5 | H21: =SUM(H13)*$S10 -> 59879.1 | I21: =SUM(I13)*$S10 -> 63401.4 | ... M21: =SUM(M13)*$S10 -> 70446 | N21: =SUM(B21:M21) -> 686848.5
A22: Payroll Burden (7.65%) | B22: =(B18+B19+B20)*0.0765 -> 3986.5298 | C22: =(C18+C19+C20)*0.0765 -> 7318.755 | D22: =(D18+D19+D20)*0.0765 -> 7318.755 | E22: =(E18+E19+E20)*0.0765 -> 7318.755 | F22: =(F18+F19+F20)*0.0765 -> 7318.755 | G22: =(G18+G19+G20)*0.0765 -> 7318.755 | H22: =(H18+H19+H20)*0.0765 -> 9189.639 | I22: =(I18+I19+I20)*0.0765 -> 9379.206 | ... M22: =(M18+M19+M20)*0.0765 -> 9758.34 | N22: =SUM(B22:M22) -> 98182.51
A23: Benefit Pkg. ($700/emp) | B23: =SUM(B10)*700 -> 12600 | C23: =SUM(C10)*700 -> 23800 | D23: =SUM(D10)*700 -> 23800 | E23: =SUM(E10)*700 -> 23800 | F23: =SUM(F10)*700 -> 23800 | G23: =SUM(G10)*700 -> 23800 | H23: =SUM(H10)*700 -> 31500 | I23: =SUM(I10)*700 -> 31500 | ... M23: =SUM(M10)*700 -> 31500 | N23: =SUM(B23:M23) -> 320600
A24: 401 K (Matching 3%) | B24: =SUM(B18:B21)*3% -> 2091.69 | C24: =SUM(C18:C21)*3% -> 4455.135 | D24: =SUM(D18:D21)*3% -> 4455.135 | E24: =SUM(E18:E21)*3% -> 4455.135 | F24: =SUM(F18:F21)*3% -> 4455.135 | G24: =SUM(G18:G21)*3% -> 4455.135 | H24: =SUM(H18:H21)*3% -> 5400.153 | I24: =SUM(I18:I21)*3% -> 5580.162 | ... M24: =SUM(M18:M21)*3% -> 5940.18 | N24: =SUM(B24:M24) -> 59108.4
A25: Leads | B25: 800 | C25: 800 | D25: =SUM(500*D8) -> 9000 | E25: =SUM(500*E8) -> 9000 | F25: =SUM(500*F8) -> 9000 | G25: =SUM(500*G8) -> 9000 | H25: =SUM(500*H8) -> 12000 | I25: =SUM(500*I8) -> 12000 | J25: =SUM(500*J8) -> 12000 | K25: =SUM(500*K8) -> 12000 | ... M25: =SUM(500*M8) -> 12000 | N25: =SUM(B25:M25) -> 109600
A26: CRM | B26: =39*B10+39 -> 741 | C26: =39*C10 -> 1326 | D26: =39*D10 -> 1326 | E26: =39*E10 -> 1326 | F26: =39*F10 -> 1326 | G26: =39*G10 -> 1326 | H26: =39*H10 -> 1755 | I26: =39*I10 -> 1755 | J26: =39*J10 -> 1755 | ... M26: =39*M10 -> 1755 | N26: =SUM(B26:M26) -> 17901
A27: Phone (Phone, Voicemail, Video) | B27: =SUM(28*B6)+(52*B7)+52 -> 460 | C27: =SUM(28*C6)+(52*C7)+52 -> 460 | D27: =SUM(28*D6)+(52*D7)+52 -> 460 | E27: =SUM(28*E6)+(52*E7)+52 -> 460 | F27: =SUM(28*F6)+(52*F7)+52 -> 460 | G27: =SUM(28*G6)+(52*G7)+52 -> 460 | H27: =SUM(28*H6)+(52*H7)+52 -> 596 | I27: =SUM(28*I6)+(52*I7)+52 -> 596 | ... M27: =SUM(28*M6)+(52*M7)+52 -> 596 | N27: =SUM(B27:M27) -> 6336
A28: Recruiting Ads | B28: 850 | C28: 850 | D28: 850 | E28: 850 | F28: 850 | G28: 850 | H28: 850 | I28: 850 | J28: 850 | K28: 850 | L28: 850 | M28: 850 | N28: =SUM(B28:M28) -> 10200
A29: TSR Field Training | B29: =SUM(B8*500) -> 3000 | C29: 1800 | D29: 1800 | E29: =SUM(E8*750) -> 13500 | F29: =SUM(F8*750) -> 13500 | G29: =SUM(G8*750) -> 13500 | H29: =SUM(H8*750) -> 18000 | I29: =SUM(I8*750) -> 18000 | J29: =SUM(J8*750) -> 18000 | K29: =SUM(K8*750) -> 18000 | L29: =SUM(L8*750) -> 18000 | M29: =SUM(M8*750) -> 18000 | N29: =SUM(B29:M29) -> 155100
A30: TSR Per Diem | B30: =500*B8 -> 3000 | C30: =500*C8 -> 9000 | D30: =500*D8 -> 9000 | E30: =500*E8 -> 9000 | F30: =500*F8 -> 9000 | G30: =500*G8 -> 9000 | H30: =500*H8 -> 12000 | I30: =500*I8 -> 12000 | ... M30: =500*M8 -> 12000 | N30: =SUM(B30:M30) -> 120000
A31: TSR Car/Fuel Allowance | B31: =600*B8 -> 3600 | C31: =600*C8 -> 10800 | D31: =600*D8 -> 10800 | E31: =600*E8 -> 10800 | F31: =600*F8 -> 10800 | G31: =600*G8 -> 10800 | H31: =600*H8 -> 14400 | I31: =600*I8 -> 14400 | ... M31: =600*M8 -> 14400 | N31: =SUM(B31:M31) -> 144000
A32: TSR Phone Allowance | B32: =25*B8 -> 150 | C32: =25*C8 -> 450 | D32: =25*D8 -> 450 | E32: =25*E8 -> 450 | F32: =25*F8 -> 450 | G32: =25*G8 -> 450 | H32: =25*H8 -> 600 | I32: =25*I8 -> 600 | ... M32: =25*M8 -> 600 | N32: =SUM(B32:M32) -> 6000
A33: TSR Hotel-2wk/mo travel | B33: =1800*B8 -> 10800 | C33: =1800*C8 -> 32400 | D33: =1800*D8 -> 32400 | E33: =1800*E8 -> 32400 | F33: =1800*F8 -> 32400 | G33: =1800*G8 -> 32400 | H33: =1800*H8 -> 43200 | I33: =1800*I8 -> 43200 | ... M33: =1800*M8 -> 43200 | N33: =SUM(B33:M33) -> 432000
A34: CC Fees (Square/In-Field) | B34: =SUM(B13*4%) -> 1194 | C34: =SUM(C13*4%) -> 3582 | D34: =SUM(D13*4%) -> 3582 | E34: =SUM(E13*4%) -> 3582 | F34: =SUM(F13*4%) -> 3582 | G34: =SUM(G13*4%) -> 3582 | H34: =SUM(H13*4%) -> 4059.6 | I34: =SUM(I13*4%) -> 4298.4 | ... M34: =SUM(M13*4%) -> 4776 | N34: =SUM(B34:M34) -> 46566
A35: Printing
A36: Brochures (Leave Behinds) | B36: 500 | C36: =SUM(C8)*50 -> 900 | D36: =SUM(D8)*50 -> 900 | E36: =SUM(E8)*50 -> 900 | F36: =SUM(F8)*50 -> 900 | G36: =SUM(G8)*50 -> 900 | H36: =SUM(H8)*50 -> 1200 | I36: =SUM(I8)*50 -> 1200 | J36: =SUM(J8)*50 -> 1200 | ... M36: =SUM(M8)*50 -> 1200 | N36: =SUM(B36:M36) -> 12200
A37: Agreements (2-part) | C37: 0 | D37: 0 | E37: 0 | F37: 0 | G37: 0 | H37: 1000 | I37: 0 | J37: 0 | K37: 0 | N37: =SUM(B37:M37) -> 1000
A38: Business Cards: TSR | C38: =SUM(C8*105) -> 1890 | D38: 0 | E38: 0 | F38: 0 | G38: 0 | H38: =SUM(H8*105) -> 2520 | I38: 0 | J38: 0 | K38: 0 | L38: 0 | M38: 0 | N38: =SUM(B38:M38) -> 4410
A39: Business Cards: RSM | B39: =SUM(B9*56) -> 0 | H39: =SUM(H9*105) -> 420 | I39: 0 | J39: 0 | K39: 0 | L39: 0 | M39: 0 | N39: =SUM(B39:M39) -> 420
A40: Business Cards: CSO | B40: =SUM(B5*105) -> 0 | C40: 0 | D40: 0 | E40: 0 | F40: 0 | G40: 0 | H40: 0 | I40: 0 | J40: 0 | K40: 0 | L40: 0 | M40: 0 | N40: =SUM(B40:M40) -> 0
A41: TOTAL | B41: =SUM(B18:B34) -> 112996.22 | C41: =SUM(C18:C34) -> 245546.39 | D41: =SUM(D18:D34) -> 253746.39 | E41: =SUM(E18:E34) -> 265446.39 | F41: =SUM(F18:F34) -> 265446.39 | G41: =SUM(G18:G34) -> 265446.39 | H41: =SUM(H18:H34) -> 333555.49 | I41: =SUM(I18:I34) -> 340164.17 | ... M41: =SUM(M18:M34) -> 353381.52 | N41: =SUM(N21:N34) -> 2212442.4
...

Sheet FE Sales YR 5
B1: FRONT END SALES FORECAST (YR 5 Maintaining) | P1: **Green boxes can be changed to modify forecast
B2: 44551 | C2: 44582 | D2: 44613 | E2: 44641 | F2: 44672 | G2: 44702 | H2: 44733 | I2: 44763 | J2: 44794 | K2: 44825 | L2: 44855 | M2: 44886
A3: Month # | B3: 1 | C3: 2 | D3: 3 | E3: 4 | F3: 5 | G3: 6 | H3: 7 | I3: 8 | J3: 9 | K3: 10 | L3: 11 | M3: 12 | N3: TOTAL | P3: SALES TEAM
A4: FE SALES HEAD COUNT | P4: Position | Q4: Salary | R4: Comm %* | S4: Survey Fee%
A5: CSO | B5: =SUM('FE Sales YR 4'!M5) -> 1 | C5: 1 | D5: 1 | E5: 1 | F5: 1 | G5: 1 | H5: 1 | I5: 1 | J5: 1 | K5: 1 | L5: 1 | M5: 1 | N5: =SUM(M5) -> 1 | P5: CSO | Q5: 0 | R5: 0.015 | S5: 0.015
A6: BC | B6: =SUM('FE Sales YR 4'!M6) -> 12 | C6: 12 | D6: 12 | E6: 12 | F6: 12 | G6: 12 | H6: 12 | I6: 12 | J6: 12 | K6: 12 | L6: 12 | M6: 12 | N6: =SUM(M6) -> 12 | P6: BC | Q6: 2500 | R6: 0.0125 | S6: 0.0125
A7: TMM | B7: =SUM('FE Sales YR 4'!M7) -> 4 | C7: 4 | D7: 4 | E7: 4 | F7: 4 | G7: 4 | H7: 4 | I7: 4 | J7: 4 | K7: 4 | L7: 4 | M7: 4 | N7: =SUM(M7) -> 4 | P7: TMM | Q7: 0 | R7: 0.01 | S7: 0.01
A8: TSR | B8: =SUM('FE Sales YR 4'!M8) -> 24 | C8: 24 | D8: 24 | E8: 24 | F8: 24 | G8: 24 | H8: 24 | I8: 24 | J8: 24 | K8: 24 | L8: 24 | M8: 24 | N8: =SUM(M8) -> 24 | P8: TSR | Q8: 2000 | R8: 0.04 | S8: 0.5
A9: RSM | B9: =SUM('FE Sales YR 4'!M9) -> 4 | C9: 4 | D9: 4 | E9: 4 | F9: 4 | G9: 4 | H9: 4 | I9: 4 | J9: 4 | K9: 4 | L9: 4 | M9: 4 | N9: =SUM(M9) -> 4 | P9: RSM | Q9: 0 | R9: 0.0175 | S9: 0.05
A10: TOTAL | B10: =SUM(B5:B9) -> 45 | C10: =SUM(C5:C9) -> 45 | D10: =SUM(D5:D9) -> 45 | E10: =SUM(E5:E9) -> 45 | F10: =SUM(F5:F9) -> 45 | G10: =SUM(G5:G9) -> 45 | H10: =SUM(H5:H9) -> 45 | I10: =SUM(I5:I9) -> 45 | ... N10: =SUM(N5:N9) -> 45 | R10: =SUM(R5:R9) -> 0.095 | S10: =SUM(S5:S9) -> 0.5875
A12: REVENUE | P12: ASSUMPTIONS
A13: Survey Fees | B13: =B8*$Q$13*$Q$14 -> 119400 | C13: =C8*$Q$13*$Q$14 -> 119400 | D13: =D8*$Q$13*$Q$14 -> 119400 | E13: =E8*$Q$13*$Q$14 -> 119400 | F13: =F8*$Q$13*$Q$14 -> 119400 | G13: =G8*$Q$13*$Q$14 -> 119400 | H13: =H8*$Q$13*$Q$14 -> 119400 | I13: =I8*$Q$13*$Q$14 -> 119400 | ... M13: =M8*$Q$13*$Q$14 -> 119400 | N13: =SUM(B13:M13) -> 1432800 | P13: # Mo Sales per TSR | Q13: 5
A14: Cash Collect | B14: =B8*$Q$13*$Q$15*$Q$16*$Q$17 -> 2832000 | C14: =C8*$Q$13*$Q$15*$Q$16*$Q$17 -> 2832000 | D14: =D8*$Q$13*$Q$15*$Q$16*$Q$17 -> 2832000 | E14: =E8*$Q$13*$Q$15*$Q$16*$Q$17 -> 2832000 | F14: =F8*$Q$13*$Q$15*$Q$16*$Q$17 -> 2832000 | G14: =G8*$Q$13*$Q$15*$Q$16*$Q$17 -> 2832000 | H14: =H8*$Q$13*$Q$15*$Q$16*$Q$17 -> 2832000 | I14: =I8*$Q$13*$Q$15*$Q$16*$Q$17 -> 2832000 | ... M14: =M8*$Q$13*$Q$15*$Q$16*$Q$17 -> 2832000 | N14: =SUM(B14:M14) -> 33984000 | P14: Avg Survey Fee | Q14: 995
A15: TOTAL | B15: =SUM(B13:B14) -> 2951400 | C15: =SUM(C13:C14) -> 2951400 | D15: =SUM(D13:D14) -> 2951400 | E15: =SUM(E13:E14) -> 2951400 | F15: =SUM(F13:F14) -> 2951400 | G15: =SUM(G13:G14) -> 2951400 | H15: =SUM(H13:H14) -> 2951400 | I15: =SUM(I13:I14) -> 2951400 | ... N15: =SUM(N13:N14) -> 35416800 | P15: Survey Closing % | Q15: 0.5
P16: Avg Hrs per Go | Q16: 160
A17: COST OF SALES | P17: Avg Rate per Hr | Q17: 295
A18: Salaries | B18: =B5*$Q$5+B6*$Q$6+C7*$Q$7+B8*$Q$8+B9*$Q$9+B13*S5+B13*S6+B13*S7+B13*S8+B13*S9 -> 148147.5 | C18: =C5*$Q$5+C6*$Q$6+D7*$Q$7+C8*$Q$8+C9*$Q$9+C13*T5+C13*T6+C13*T7+C13*T8+C13*T9 -> 78000 | D18: =D5*$Q$5+D6*$Q$6+E7*$Q$7+D8*$Q$8+D9*$Q$9+D13*U5+D13*U6+D13*U7+D13*U8+D13*U9 -> 78000 | E18: =E5*$Q$5+E6*$Q$6+F7*$Q$7+E8*$Q$8+E9*$Q$9+E13*V5+E13*V6+E13*V7+E13*V8+E13*V9 -> 78000 | F18: =F5*$Q$5+F6*$Q$6+G7*$Q$7+F8*$Q$8+F9*$Q$9+F13*W5+F13*W6+F13*W7+F13*W8+F13*W9 -> 78000 | G18: =G5*$Q$5+G6*$Q$6+H7*$Q$7+G8*$Q$8+G9*$Q$9+G13*X5+G13*X6+G13*X7+G13*X8+G13*X9 -> 78000 | H18: =H5*$Q$5+H6*$Q$6+I7*$Q$7+H8*$Q$8+H9*$Q$9+H13*Y5+H13*Y6+H13*Y7+H13*Y8+H13*Y9 -> 78000 | I18: =I5*$Q$5+I6*$Q$6+J7*$Q$7+I8*$Q$8+I9*$Q$9+I13*Z5+I13*Z6+I13*Z7+I13*Z8+I13*Z9 -> 78000 | ... M18: =M5*$Q$5+M6*$Q$6+N7*$Q$7+M8*$Q$8+M9*$Q$9+M13*AD5+M13*AD6+M13*AD7+M13*AD8+M13*AD9 -> 78000 | N18: =SUM(B18:M18) -> 1006147.5 | P18: Est. Sale Bonuses | Q18: =IF(Q13>5,(Q13-4)*300,0) -> 0
A19: Commission | B19: =IF(B5>0,$R$5*B$14,0) -> 42480 | C19: =IF(C5>0,$R$5*C$14,0) -> 42480 | D19: =IF(D5>0,$R$5*D$14,0) -> 42480 | E19: =IF(E5>0,$R$5*E$14,0) -> 42480 | F19: =IF(F5>0,$R$5*F$14,0) -> 42480 | G19: =IF(G5>0,$R$5*G$14,0) -> 42480 | H19: =IF(H5>0,$R$5*H$14,0) -> 42480 | I19: =IF(I5>0,$R$5*I$14,0) -> 42480 | ... M19: =IF(M5>0,$R$5*M$14,0) -> 42480 | N19: =SUM(B19:M19) -> 509760 | P19: Est. Srvy Fee Bonus | Q19: =IF($Q$14>995,($Q$14-995)*0.5*$Q$13,0) -> 0
A20: Bonus | B20: =IF(B8>0,B8*$Q$18+B8*$Q$19,0) -> 0 | C20: =IF(C8>0,C8*$Q$18+C8*$Q$19,0) -> 0 | D20: =IF(D8>0,D8*$Q$18+D8*$Q$19,0) -> 0 | E20: =IF(E8>0,E8*$Q$18+E8*$Q$19,0) -> 0 | F20: =IF(F8>0,F8*$Q$18+F8*$Q$19,0) -> 0 | G20: =IF(G8>0,G8*$Q$18+G8*$Q$19,0) -> 0 | H20: =IF(H8>0,H8*$Q$18+H8*$Q$19,0) -> 0 | I20: =IF(I8>0,I8*$Q$18+I8*$Q$19,0) -> 0 | ... M20: =IF(M8>0,M8*$Q$18+M8*$Q$19,0) -> 0 | N20: =SUM(B20:M20) -> 0
A21: FE Sales (Survey Fee %) | B21: =SUM(B13)*$S10 -> 70147.5 | C21: =SUM(C13)*$S10 -> 70147.5 | D21: =SUM(D13)*$S10 -> 70147.5 | E21: =SUM(E13)*$S10 -> 70147.5 | F21: =SUM(F13)*$S10 -> 70147.5 | G21: =SUM(G13)*$S10 -> 70147.5 | H21: =SUM(H13)*$S10 -> 70147.5 | I21: =SUM(I13)*$S10 -> 70147.5 | ... M21: =SUM(M13)*$S10 -> 70147.5 | N21: =SUM(B21:M21) -> 841770
A22: Payroll Burden (7.65%) | B22: =(B18+B19+B20)*0.0765 -> 14583.004 | C22: =(C18+C19+C20)*0.0765 -> 9216.72 | D22: =(D18+D19+D20)*0.0765 -> 9216.72 | E22: =(E18+E19+E20)*0.0765 -> 9216.72 | F22: =(F18+F19+F20)*0.0765 -> 9216.72 | G22: =(G18+G19+G20)*0.0765 -> 9216.72 | H22: =(H18+H19+H20)*0.0765 -> 9216.72 | I22: =(I18+I19+I20)*0.0765 -> 9216.72 | ... M22: =(M18+M19+M20)*0.0765 -> 9216.72 | N22: =SUM(B22:M22) -> 115966.92
A23: Benefit Pkg. ($700/emp) | B23: =SUM(B10)*700 -> 31500 | C23: =SUM(C10)*700 -> 31500 | D23: =SUM(D10)*700 -> 31500 | E23: =SUM(E10)*700 -> 31500 | F23: =SUM(F10)*700 -> 31500 | G23: =SUM(G10)*700 -> 31500 | H23: =SUM(H10)*700 -> 31500 | I23: =SUM(I10)*700 -> 31500 | ... M23: =SUM(M10)*700 -> 31500 | N23: =SUM(B23:M23) -> 378000
A24: 401 K (Matching 3%) | B24: =SUM(B18:B21)*3% -> 7823.25 | C24: =SUM(C18:C21)*3% -> 5718.825 | D24: =SUM(D18:D21)*3% -> 5718.825 | E24: =SUM(E18:E21)*3% -> 5718.825 | F24: =SUM(F18:F21)*3% -> 5718.825 | G24: =SUM(G18:G21)*3% -> 5718.825 | H24: =SUM(H18:H21)*3% -> 5718.825 | I24: =SUM(I18:I21)*3% -> 5718.825 | ... M24: =SUM(M18:M21)*3% -> 5718.825 | N24: =SUM(B24:M24) -> 70730.325
A25: Leads | B25: 800 | C25: 800 | D25: =SUM(500*D8) -> 12000 | E25: =SUM(500*E8) -> 12000 | F25: =SUM(500*F8) -> 12000 | G25: =SUM(500*G8) -> 12000 | H25: =SUM(500*H8) -> 12000 | I25: =SUM(500*I8) -> 12000 | J25: =SUM(500*J8) -> 12000 | K25: =SUM(500*K8) -> 12000 | ... M25: =SUM(500*M8) -> 12000 | N25: =SUM(B25:M25) -> 121600
A26: CRM | B26: =39*B10+39 -> 1794 | C26: =39*C10 -> 1755 | D26: =39*D10 -> 1755 | E26: =39*E10 -> 1755 | F26: =39*F10 -> 1755 | G26: =39*G10 -> 1755 | H26: =39*H10 -> 1755 | I26: =39*I10 -> 1755 | J26: =39*J10 -> 1755 | ... M26: =39*M10 -> 1755 | N26: =SUM(B26:M26) -> 21099
A27: Phone (Phone, Voicemail, Video) | B27: =SUM(28*B6)+(52*B7)+52 -> 596 | C27: =SUM(28*C6)+(52*C7)+52 -> 596 | D27: =SUM(28*D6)+(52*D7)+52 -> 596 | E27: =SUM(28*E6)+(52*E7)+52 -> 596 | F27: =SUM(28*F6)+(52*F7)+52 -> 596 | G27: =SUM(28*G6)+(52*G7)+52 -> 596 | H27: =SUM(28*H6)+(52*H7)+52 -> 596 | I27: =SUM(28*I6)+(52*I7)+52 -> 596 | ... M27: =SUM(28*M6)+(52*M7)+52 -> 596 | N27: =SUM(B27:M27) -> 7152
A28: Recruiting Ads | B28: 850 | C28: 850 | D28: 850 | E28: 850 | F28: 850 | G28: 850 | H28: 850 | I28: 850 | J28: 850 | K28: 850 | L28: 850 | M28: 850 | N28: =SUM(B28:M28) -> 10200
A29: TSR Field Training | B29: =SUM(B8*500) -> 12000 | C29: 1800 | D29: 1800 | E29: =SUM(E8*750) -> 18000 | F29: =SUM(F8*750) -> 18000 | G29: =SUM(G8*750) -> 18000 | H29: =SUM(H8*750) -> 18000 | I29: =SUM(I8*750) -> 18000 | J29: =SUM(J8*750) -> 18000 | K29: =SUM(K8*750) -> 18000 | L29: =SUM(L8*750) -> 18000 | M29: =SUM(M8*750) -> 18000 | N29: =SUM(B29:M29) -> 177600
A30: TSR Per Diem | B30: =500*B8 -> 12000 | C30: =500*C8 -> 12000 | D30: =500*D8 -> 12000 | E30: =500*E8 -> 12000 | F30: =500*F8 -> 12000 | G30: =500*G8 -> 12000 | H30: =500*H8 -> 12000 | I30: =500*I8 -> 12000 | ... M30: =500*M8 -> 12000 | N30: =SUM(B30:M30) -> 144000
A31: TSR Car/Fuel Allowance | B31: =600*B8 -> 14400 | C31: =600*C8 -> 14400 | D31: =600*D8 -> 14400 | E31: =600*E8 -> 14400 | F31: =600*F8 -> 14400 | G31: =600*G8 -> 14400 | H31: =600*H8 -> 14400 | I31: =600*I8 -> 14400 | ... M31: =600*M8 -> 14400 | N31: =SUM(B31:M31) -> 172800
A32: TSR Phone Allowance | B32: =25*B8 -> 600 | C32: =25*C8 -> 600 | D32: =25*D8 -> 600 | E32: =25*E8 -> 600 | F32: =25*F8 -> 600 | G32: =25*G8 -> 600 | H32: =25*H8 -> 600 | I32: =25*I8 -> 600 | ... M32: =25*M8 -> 600 | N32: =SUM(B32:M32) -> 7200
A33: TSR Hotel-2wk/mo travel | B33: =1800*B8 -> 43200 | C33: =1800*C8 -> 43200 | D33: =1800*D8 -> 43200 | E33: =1800*E8 -> 43200 | F33: =1800*F8 -> 43200 | G33: =1800*G8 -> 43200 | H33: =1800*H8 -> 43200 | I33: =1800*I8 -> 43200 | ... M33: =1800*M8 -> 43200 | N33: =SUM(B33:M33) -> 518400
A34: CC Fees (Square/In-Field) | B34: =SUM(B13*4%) -> 4776 | C34: =SUM(C13*4%) -> 4776 | D34: =SUM(D13*4%) -> 4776 | E34: =SUM(E13*4%) -> 4776 | F34: =SUM(F13*4%) -> 4776 | G34: =SUM(G13*4%) -> 4776 | H34: =SUM(H13*4%) -> 4776 | I34: =SUM(I13*4%) -> 4776 | ... M34: =SUM(M13*4%) -> 4776 | N34: =SUM(B34:M34) -> 57312
A35: Printing
A36: Brochures (Leave Behinds) | B36: 500 | C36: =SUM(C8)*50 -> 1200 | D36: =SUM(D8)*50 -> 1200 | E36: =SUM(E8)*50 -> 1200 | F36: =SUM(F8)*50 -> 1200 | G36: =SUM(G8)*50 -> 1200 | H36: =SUM(H8)*50 -> 1200 | I36: =SUM(I8)*50 -> 1200 | J36: =SUM(J8)*50 -> 1200 | ... M36: =SUM(M8)*50 -> 1200 | N36: =SUM(B36:M36) -> 13700
A37: Agreements (2-part) | C37: 0 | D37: 0 | E37: 0 | F37: 0 | G37: 0 | H37: 1250 | I37: 0 | J37: 0 | K37: 0 | N37: =SUM(B37:M37) -> 1250
A38: Business Cards: TSR | C38: =SUM(C8*105) -> 2520 | D38: 0 | E38: 0 | F38: 0 | G38: 0 | H38: =SUM(H8*105) -> 2520 | I38: 0 | J38: 0 | K38: 0 | L38: 0 | M38: 0 | N38: =SUM(B38:M38) -> 5040
A39: Business Cards: RSM | B39: =SUM(B9*56) -> 224 | H39: =SUM(H9*105) -> 420 | I39: 0 | J39: 0 | K39: 0 | L39: 0 | M39: 0 | N39: =SUM(B39:M39) -> 644
A40: Business Cards: CSO | B40: =SUM(B5*105) -> 105 | C40: 0 | D40: 0 | E40: 0 | F40: 0 | G40: 0 | H40: 0 | I40: 0 | J40: 0 | K40: 0 | L40: 0 | M40: 0 | N40: =SUM(B40:M40) -> 105
A41: TOTAL | B41: =SUM(B18:B34) -> 405697.25 | C41: =SUM(C18:C34) -> 317840.05 | D41: =SUM(D18:D34) -> 329040.05 | E41: =SUM(E18:E34) -> 345240.05 | F41: =SUM(F18:F34) -> 345240.05 | G41: =SUM(G18:G34) -> 345240.05 | H41: =SUM(H18:H34) -> 345240.05 | I41: =SUM(I18:I34) -> 345240.05 | ... N41: =SUM(N18:N34) -> 4159737.7
...
